<?xml version="1.0" encoding="UTF-8"?>
<testng-results skipped="0" failed="1" ignored="0" total="2" passed="1">
  <reporter-output>
  </reporter-output>
  <suite name="Suite" duration-ms="55" started-at="2018-02-23T19:12:46Z" finished-at="2018-02-23T19:12:46Z">
    <groups>
    </groups>
    <test name="Test" duration-ms="55" started-at="2018-02-23T19:12:46Z" finished-at="2018-02-23T19:12:46Z">
      <class name="Test.test">
        <test-method status="FAIL" signature="dummy_test_to_fail()[pri:0, instance:Test.test@5594a1b5]" name="dummy_test_to_fail" duration-ms="10" started-at="2018-02-23T21:12:46Z" finished-at="2018-02-23T21:12:46Z">
          <exception class="java.lang.AssertionError">
            <message>
              <![CDATA[expected [2] but found [1]]]>
            </message>
            <full-stacktrace>
              <![CDATA[java.lang.AssertionError: expected [2] but found [1]at org.testng.Assert.fail(Assert.java:96)at org.testng.Assert.failNotEquals(Assert.java:776)at org.testng.Assert.assertEqualsImpl(Assert.java:137)at org.testng.Assert.assertEquals(Assert.java:118)at org.testng.Assert.assertEquals(Assert.java:652)at org.testng.Assert.assertEquals(Assert.java:662)at Test.test.dummy_test_to_fail(test.java:16)at sun.reflect.NativeMethodAccessorImpl.invoke0(Native Method)at sun.reflect.NativeMethodAccessorImpl.invoke(Unknown Source)at sun.reflect.DelegatingMethodAccessorImpl.invoke(Unknown Source)at java.lang.reflect.Method.invoke(Unknown Source)at org.testng.internal.MethodInvocationHelper.invokeMethod(MethodInvocationHelper.java:124)at org.testng.internal.Invoker.invokeMethod(Invoker.java:571)at org.testng.internal.Invoker.invokeTestMethod(Invoker.java:707)at org.testng.internal.Invoker.invokeTestMethods(Invoker.java:979)at org.testng.internal.TestMethodWorker.invokeTestMethods(TestMethodWorker.java:125)at org.testng.internal.TestMethodWorker.run(TestMethodWorker.java:109)at org.testng.TestRunner.privateRun(TestRunner.java:648)at org.testng.TestRunner.run(TestRunner.java:505)at org.testng.SuiteRunner.runTest(SuiteRunner.java:455)at org.testng.SuiteRunner.runSequentially(SuiteRunner.java:450)at org.testng.SuiteRunner.privateRun(SuiteRunner.java:415)at org.testng.SuiteRunner.run(SuiteRunner.java:364)at org.testng.SuiteRunnerWorker.runSuite(SuiteRunnerWorker.java:52)at org.testng.SuiteRunnerWorker.run(SuiteRunnerWorker.java:84)at org.testng.TestNG.runSuitesSequentially(TestNG.java:1187)at org.testng.TestNG.runSuitesLocally(TestNG.java:1116)at org.testng.TestNG.runSuites(TestNG.java:1028)at org.testng.TestNG.run(TestNG.java:996)at org.apache.maven.surefire.testng.TestNGExecutor.run(TestNGExecutor.java:281)at org.apache.maven.surefire.testng.TestNGXmlTestSuite.execute(TestNGXmlTestSuite.java:75)at org.apache.maven.surefire.testng.TestNGProvider.invoke(TestNGProvider.java:121)at org.apache.maven.surefire.booter.ForkedBooter.invokeProviderInSameClassLoader(ForkedBooter.java:290)at org.apache.maven.surefire.booter.ForkedBooter.runSuitesInProcess(ForkedBooter.java:242)at org.apache.maven.surefire.booter.ForkedBooter.main(ForkedBooter.java:121)]]>
            </full-stacktrace>
          </exception> <!-- java.lang.AssertionError -->
          <reporter-output>
          </reporter-output>
        </test-method> <!-- dummy_test_to_fail -->
        <test-method status="PASS" signature="dummy_test_to_pass()[pri:0, instance:Test.test@5594a1b5]" name="dummy_test_to_pass" duration-ms="0" started-at="2018-02-23T21:12:46Z" finished-at="2018-02-23T21:12:46Z">
          <reporter-output>
          </reporter-output>
        </test-method> <!-- dummy_test_to_pass -->
      </class> <!-- Test.test -->
    </test> <!-- Test -->
  </suite> <!-- Suite -->
</testng-results>
